2025-02-11 13:43:08,807 - ERROR - Exception on /productadddb [POST]
Traceback (most recent call last):
  File "/home/username/fashionholics/venv/lib/python3.12/site-packages/flask/app.py", line 1473, in wsgi_app
    response = self.full_dispatch_request()
               ^^^^^^^^^^^^^^^^^^^^^^^^^^^^
  File "/home/username/fashionholics/venv/lib/python3.12/site-packages/flask/app.py", line 882, in full_dispatch_request
    rv = self.handle_user_exception(e)
         ^^^^^^^^^^^^^^^^^^^^^^^^^^^^^
  File "/home/username/fashionholics/venv/lib/python3.12/site-packages/flask/app.py", line 880, in full_dispatch_request
    rv = self.dispatch_request()
         ^^^^^^^^^^^^^^^^^^^^^^^
  File "/home/username/fashionholics/venv/lib/python3.12/site-packages/flask/app.py", line 865, in dispatch_request
    return self.ensure_sync(self.view_functions[rule.endpoint])(**view_args)  # type: ignore[no-any-return]
           ^^^^^^^^^^^^^^^^^^^^^^^^^^^^^^^^^^^^^^^^^^^^^^^^^^^^^^^^^^^^^^^^^
  File "/home/username/fashionholics/main.py", line 1583, in productadddb
    my_cursor.execute("INSERT INTO products (name, description, color, price, per1, per2, per3, sku, quantity, category, gender, size, img1, img2, img3, img4, img5, vendor, coloroptions, created_at) VALUES (?, ?, ?, ?, ?, ?, ?, ?, ?, ?, ?, ?, ?, ?, ?, ?, ?, ?, ?, CURRENT_TIMESTAMP)", (productname, description, color, baseprice, discountpercentage1, discountpercentage2, discountpercentage3, sku, quantity, productcategory, gender, sizes, input1, input2, input3, input4, input5, vendor, coloroption))
sqlite3.OperationalError: database is locked
2025-02-15 19:59:20,603 - ERROR - Exception on /product [GET]
Traceback (most recent call last):
  File "/home/username/fashionholics/venv/lib/python3.12/site-packages/flask/app.py", line 1473, in wsgi_app
    response = self.full_dispatch_request()
               ^^^^^^^^^^^^^^^^^^^^^^^^^^^^
  File "/home/username/fashionholics/venv/lib/python3.12/site-packages/flask/app.py", line 882, in full_dispatch_request
    rv = self.handle_user_exception(e)
         ^^^^^^^^^^^^^^^^^^^^^^^^^^^^^
  File "/home/username/fashionholics/venv/lib/python3.12/site-packages/flask/app.py", line 880, in full_dispatch_request
    rv = self.dispatch_request()
         ^^^^^^^^^^^^^^^^^^^^^^^
  File "/home/username/fashionholics/venv/lib/python3.12/site-packages/flask/app.py", line 865, in dispatch_request
    return self.ensure_sync(self.view_functions[rule.endpoint])(**view_args)  # type: ignore[no-any-return]
           ^^^^^^^^^^^^^^^^^^^^^^^^^^^^^^^^^^^^^^^^^^^^^^^^^^^^^^^^^^^^^^^^^
  File "/home/username/fashionholics/main.py", line 985, in product
    return render_template('product-layout-1.html', productname=productname, productprice=productprice, message=message)
           ^^^^^^^^^^^^^^^^^^^^^^^^^^^^^^^^^^^^^^^^^^^^^^^^^^^^^^^^^^^^^^^^^^^^^^^^^^^^^^^^^^^^^^^^^^^^^^^^^^^^^^^^^^^^^
  File "/home/username/fashionholics/venv/lib/python3.12/site-packages/flask/templating.py", line 150, in render_template
    return _render(app, template, context)
           ^^^^^^^^^^^^^^^^^^^^^^^^^^^^^^^
  File "/home/username/fashionholics/venv/lib/python3.12/site-packages/flask/templating.py", line 131, in _render
    rv = template.render(context)
         ^^^^^^^^^^^^^^^^^^^^^^^^
  File "/home/username/fashionholics/venv/lib/python3.12/site-packages/jinja2/environment.py", line 1304, in render
    self.environment.handle_exception()
  File "/home/username/fashionholics/venv/lib/python3.12/site-packages/jinja2/environment.py", line 939, in handle_exception
    raise rewrite_traceback_stack(source=source)
  File "/home/username/fashionholics/templates/product-layout-1.html", line 572, in top-level template code
    <a data-image="../static/images/pics/{{name[12]}}"
    ^^^^^^^^^^^^^^^^^^^^^^^^^
  File "/home/username/fashionholics/venv/lib/python3.12/site-packages/jinja2/environment.py", line 468, in getitem
    return obj[argument]
           ~~~^^^^^^^^^^
jinja2.exceptions.UndefinedError: 'name' is undefined
2025-02-16 05:14:02,515 - ERROR - Exception on /product/26 [GET]
Traceback (most recent call last):
  File "/home/username/fashionholics/venv/lib/python3.12/site-packages/flask/app.py", line 1473, in wsgi_app
    response = self.full_dispatch_request()
               ^^^^^^^^^^^^^^^^^^^^^^^^^^^^
  File "/home/username/fashionholics/venv/lib/python3.12/site-packages/flask/app.py", line 882, in full_dispatch_request
    rv = self.handle_user_exception(e)
         ^^^^^^^^^^^^^^^^^^^^^^^^^^^^^
  File "/home/username/fashionholics/venv/lib/python3.12/site-packages/flask/app.py", line 880, in full_dispatch_request
    rv = self.dispatch_request()
         ^^^^^^^^^^^^^^^^^^^^^^^
  File "/home/username/fashionholics/venv/lib/python3.12/site-packages/flask/app.py", line 865, in dispatch_request
    return self.ensure_sync(self.view_functions[rule.endpoint])(**view_args)  # type: ignore[no-any-return]
           ^^^^^^^^^^^^^^^^^^^^^^^^^^^^^^^^^^^^^^^^^^^^^^^^^^^^^^^^^^^^^^^^^
  File "/home/username/fashionholics/main.py", line 1809, in productinfo
    coloroptions_str = my_cursor.execute("Select coloroptions from products where name=?", (productname[0],)).fetchone()
                                                                                            ~~~~~~~~~~~^^^
TypeError: 'NoneType' object is not subscriptable
